[2025-02-28T03:21:17.199+0000] {taskinstance.py:1956} INFO - Dependencies all met for dep_context=non-requeueable deps ti=<TaskInstance: crypto_etl_dag.load_to_postgres_file scheduled__2025-02-28T03:15:00+00:00 [queued]>
[2025-02-28T03:21:17.212+0000] {taskinstance.py:1956} INFO - Dependencies all met for dep_context=requeueable deps ti=<TaskInstance: crypto_etl_dag.load_to_postgres_file scheduled__2025-02-28T03:15:00+00:00 [queued]>
[2025-02-28T03:21:17.213+0000] {taskinstance.py:2170} INFO - Starting attempt 1 of 1
[2025-02-28T03:21:17.231+0000] {taskinstance.py:2191} INFO - Executing <Task(BashOperator): load_to_postgres_file> on 2025-02-28 03:15:00+00:00
[2025-02-28T03:21:17.237+0000] {standard_task_runner.py:60} INFO - Started process 140 to run task
[2025-02-28T03:21:17.243+0000] {standard_task_runner.py:87} INFO - Running: ['***', 'tasks', 'run', 'crypto_etl_dag', 'load_to_postgres_file', 'scheduled__2025-02-28T03:15:00+00:00', '--job-id', '6', '--raw', '--subdir', 'DAGS_FOLDER/crypto_etl_dag.py', '--cfg-path', '/tmp/tmpwos8i08g']
[2025-02-28T03:21:17.246+0000] {standard_task_runner.py:88} INFO - Job 6: Subtask load_to_postgres_file
[2025-02-28T03:21:17.317+0000] {task_command.py:423} INFO - Running <TaskInstance: crypto_etl_dag.load_to_postgres_file scheduled__2025-02-28T03:15:00+00:00 [running]> on host 594e1917f83a
[2025-02-28T03:21:17.425+0000] {taskinstance.py:2480} INFO - Exporting env vars: AIRFLOW_CTX_DAG_OWNER='***' AIRFLOW_CTX_DAG_ID='crypto_etl_dag' AIRFLOW_CTX_TASK_ID='load_to_postgres_file' AIRFLOW_CTX_EXECUTION_DATE='2025-02-28T03:15:00+00:00' AIRFLOW_CTX_TRY_NUMBER='1' AIRFLOW_CTX_DAG_RUN_ID='scheduled__2025-02-28T03:15:00+00:00'
[2025-02-28T03:21:17.429+0000] {subprocess.py:63} INFO - Tmp dir root location: /tmp
[2025-02-28T03:21:17.430+0000] {subprocess.py:75} INFO - Running command: ['/usr/bin/bash', '-c', 'python /opt/***/dags/scripts/load_to_postgres.py']
[2025-02-28T03:21:17.444+0000] {subprocess.py:86} INFO - Output:
[2025-02-28T03:21:18.784+0000] {subprocess.py:93} INFO - [ERROR] Lỗi khi lấy danh sách file đã xử lý: duplicate key value violates unique constraint "pg_type_typname_nsp_index"
[2025-02-28T03:21:18.785+0000] {subprocess.py:93} INFO - DETAIL:  Key (typname, typnamespace)=(processed_files, 2200) already exists.
[2025-02-28T03:21:18.786+0000] {subprocess.py:93} INFO - 
[2025-02-28T03:21:18.787+0000] {subprocess.py:93} INFO - [INFO] Đã tải file '2025/02/28/10-21-14.csv' từ MinIO
[2025-02-28T03:21:18.788+0000] {subprocess.py:93} INFO - [ERROR] Lỗi khi nạp dữ liệu vào Data Warehouse: relation "fact_coin_measurements" does not exist
[2025-02-28T03:21:18.789+0000] {subprocess.py:93} INFO - LINE 2:                 INSERT INTO fact_coin_measurements (
[2025-02-28T03:21:18.789+0000] {subprocess.py:93} INFO -                                     ^
[2025-02-28T03:21:18.790+0000] {subprocess.py:93} INFO - 
[2025-02-28T03:21:18.790+0000] {subprocess.py:93} INFO - [INFO] Quá trình ETL hoàn tất. Đã xử lý 1 file mới từ MinIO.
[2025-02-28T03:21:18.896+0000] {subprocess.py:97} INFO - Command exited with return code 0
[2025-02-28T03:21:18.931+0000] {taskinstance.py:1138} INFO - Marking task as SUCCESS. dag_id=crypto_etl_dag, task_id=load_to_postgres_file, execution_date=20250228T031500, start_date=20250228T032117, end_date=20250228T032118
[2025-02-28T03:21:18.982+0000] {local_task_job_runner.py:234} INFO - Task exited with return code 0
[2025-02-28T03:21:19.006+0000] {taskinstance.py:3280} INFO - 0 downstream tasks scheduled from follow-on schedule check
