[2025-02-27T06:01:03.299+0000] {taskinstance.py:1956} INFO - Dependencies all met for dep_context=non-requeueable deps ti=<TaskInstance: crypto_etl_dag.load_to_postgres_file manual__2025-02-27T06:00:57.494622+00:00 [queued]>
[2025-02-27T06:01:03.312+0000] {taskinstance.py:1956} INFO - Dependencies all met for dep_context=requeueable deps ti=<TaskInstance: crypto_etl_dag.load_to_postgres_file manual__2025-02-27T06:00:57.494622+00:00 [queued]>
[2025-02-27T06:01:03.313+0000] {taskinstance.py:2170} INFO - Starting attempt 1 of 1
[2025-02-27T06:01:03.329+0000] {taskinstance.py:2191} INFO - Executing <Task(BashOperator): load_to_postgres_file> on 2025-02-27 06:00:57.494622+00:00
[2025-02-27T06:01:03.337+0000] {standard_task_runner.py:60} INFO - Started process 442 to run task
[2025-02-27T06:01:03.341+0000] {standard_task_runner.py:87} INFO - Running: ['***', 'tasks', 'run', 'crypto_etl_dag', 'load_to_postgres_file', 'manual__2025-02-27T06:00:57.494622+00:00', '--job-id', '28', '--raw', '--subdir', 'DAGS_FOLDER/crypto_etl_dag.py', '--cfg-path', '/tmp/tmpswl_w7gq']
[2025-02-27T06:01:03.344+0000] {standard_task_runner.py:88} INFO - Job 28: Subtask load_to_postgres_file
[2025-02-27T06:01:03.393+0000] {task_command.py:423} INFO - Running <TaskInstance: crypto_etl_dag.load_to_postgres_file manual__2025-02-27T06:00:57.494622+00:00 [running]> on host d7538f12d10b
[2025-02-27T06:01:03.468+0000] {taskinstance.py:2480} INFO - Exporting env vars: AIRFLOW_CTX_DAG_OWNER='***' AIRFLOW_CTX_DAG_ID='crypto_etl_dag' AIRFLOW_CTX_TASK_ID='load_to_postgres_file' AIRFLOW_CTX_EXECUTION_DATE='2025-02-27T06:00:57.494622+00:00' AIRFLOW_CTX_TRY_NUMBER='1' AIRFLOW_CTX_DAG_RUN_ID='manual__2025-02-27T06:00:57.494622+00:00'
[2025-02-27T06:01:03.470+0000] {subprocess.py:63} INFO - Tmp dir root location: /tmp
[2025-02-27T06:01:03.471+0000] {subprocess.py:75} INFO - Running command: ['/usr/bin/bash', '-c', 'python /opt/***/dags/scripts/load_to_postgres.py']
[2025-02-27T06:01:03.485+0000] {subprocess.py:86} INFO - Output:
[2025-02-27T06:01:03.922+0000] {subprocess.py:93} INFO - Đã tải file 'coin_data.csv' từ MinIO về 'coin_data_from_minio.csv'
[2025-02-27T06:01:03.927+0000] {subprocess.py:93} INFO - Traceback (most recent call last):
[2025-02-27T06:01:03.928+0000] {subprocess.py:93} INFO -   File "/opt/***/dags/scripts/load_to_postgres.py", line 130, in <module>
[2025-02-27T06:01:03.928+0000] {subprocess.py:93} INFO -     load_to_postgres("coin_data_from_minio.csv", table_name="raw_coin_data")
[2025-02-27T06:01:03.928+0000] {subprocess.py:93} INFO -   File "/opt/***/dags/scripts/load_to_postgres.py", line 27, in load_to_postgres
[2025-02-27T06:01:03.929+0000] {subprocess.py:93} INFO -     conn = psycopg2.connect(
[2025-02-27T06:01:03.929+0000] {subprocess.py:93} INFO -   File "/home/***/.local/lib/python3.8/site-packages/psycopg2/__init__.py", line 122, in connect
[2025-02-27T06:01:03.929+0000] {subprocess.py:93} INFO -     conn = _connect(dsn, connection_factory=connection_factory, **kwasync)
[2025-02-27T06:01:03.930+0000] {subprocess.py:93} INFO - psycopg2.OperationalError: connection to server at "localhost" (::1), port 5432 failed: Connection refused
[2025-02-27T06:01:03.930+0000] {subprocess.py:93} INFO - 	Is the server running on that host and accepting TCP/IP connections?
[2025-02-27T06:01:03.930+0000] {subprocess.py:93} INFO - connection to server at "localhost" (127.0.0.1), port 5432 failed: Connection refused
[2025-02-27T06:01:03.931+0000] {subprocess.py:93} INFO - 	Is the server running on that host and accepting TCP/IP connections?
[2025-02-27T06:01:03.931+0000] {subprocess.py:93} INFO - 
[2025-02-27T06:01:03.951+0000] {subprocess.py:97} INFO - Command exited with return code 1
[2025-02-27T06:01:03.969+0000] {taskinstance.py:2698} ERROR - Task failed with exception
Traceback (most recent call last):
  File "/home/airflow/.local/lib/python3.8/site-packages/airflow/models/taskinstance.py", line 433, in _execute_task
    result = execute_callable(context=context, **execute_callable_kwargs)
  File "/home/airflow/.local/lib/python3.8/site-packages/airflow/operators/bash.py", line 212, in execute
    raise AirflowException(
airflow.exceptions.AirflowException: Bash command failed. The command returned a non-zero exit code 1.
[2025-02-27T06:01:03.972+0000] {taskinstance.py:1138} INFO - Marking task as FAILED. dag_id=crypto_etl_dag, task_id=load_to_postgres_file, execution_date=20250227T060057, start_date=20250227T060103, end_date=20250227T060103
[2025-02-27T06:01:03.984+0000] {standard_task_runner.py:107} ERROR - Failed to execute job 28 for task load_to_postgres_file (Bash command failed. The command returned a non-zero exit code 1.; 442)
[2025-02-27T06:01:03.994+0000] {local_task_job_runner.py:234} INFO - Task exited with return code 1
[2025-02-27T06:01:04.012+0000] {taskinstance.py:3280} INFO - 0 downstream tasks scheduled from follow-on schedule check
