[2025-02-27T05:56:09.981+0000] {taskinstance.py:1956} INFO - Dependencies all met for dep_context=non-requeueable deps ti=<TaskInstance: crypto_etl_dag.extract_coingecko_file manual__2025-02-27T05:56:08.472715+00:00 [queued]>
[2025-02-27T05:56:09.994+0000] {taskinstance.py:1956} INFO - Dependencies all met for dep_context=requeueable deps ti=<TaskInstance: crypto_etl_dag.extract_coingecko_file manual__2025-02-27T05:56:08.472715+00:00 [queued]>
[2025-02-27T05:56:09.995+0000] {taskinstance.py:2170} INFO - Starting attempt 1 of 1
[2025-02-27T05:56:10.011+0000] {taskinstance.py:2191} INFO - Executing <Task(BashOperator): extract_coingecko_file> on 2025-02-27 05:56:08.472715+00:00
[2025-02-27T05:56:10.021+0000] {standard_task_runner.py:60} INFO - Started process 326 to run task
[2025-02-27T05:56:10.024+0000] {standard_task_runner.py:87} INFO - Running: ['***', 'tasks', 'run', 'crypto_etl_dag', 'extract_coingecko_file', 'manual__2025-02-27T05:56:08.472715+00:00', '--job-id', '24', '--raw', '--subdir', 'DAGS_FOLDER/crypto_etl_dag.py', '--cfg-path', '/tmp/tmpdyx76tl2']
[2025-02-27T05:56:10.027+0000] {standard_task_runner.py:88} INFO - Job 24: Subtask extract_coingecko_file
[2025-02-27T05:56:10.089+0000] {task_command.py:423} INFO - Running <TaskInstance: crypto_etl_dag.extract_coingecko_file manual__2025-02-27T05:56:08.472715+00:00 [running]> on host d7538f12d10b
[2025-02-27T05:56:10.193+0000] {taskinstance.py:2480} INFO - Exporting env vars: AIRFLOW_CTX_DAG_OWNER='***' AIRFLOW_CTX_DAG_ID='crypto_etl_dag' AIRFLOW_CTX_TASK_ID='extract_coingecko_file' AIRFLOW_CTX_EXECUTION_DATE='2025-02-27T05:56:08.472715+00:00' AIRFLOW_CTX_TRY_NUMBER='1' AIRFLOW_CTX_DAG_RUN_ID='manual__2025-02-27T05:56:08.472715+00:00'
[2025-02-27T05:56:10.197+0000] {subprocess.py:63} INFO - Tmp dir root location: /tmp
[2025-02-27T05:56:10.199+0000] {subprocess.py:75} INFO - Running command: ['/usr/bin/bash', '-c', 'python /opt/***/dags/scripts/extract_coingecko.py']
[2025-02-27T05:56:10.215+0000] {subprocess.py:86} INFO - Output:
[2025-02-27T05:56:17.622+0000] {subprocess.py:93} INFO - [extract_coingecko] Đã lưu dữ liệu vào file 'coin_data.csv'
[2025-02-27T05:56:17.629+0000] {subprocess.py:93} INFO - Traceback (most recent call last):
[2025-02-27T05:56:17.629+0000] {subprocess.py:93} INFO -   File "/home/***/.local/lib/python3.8/site-packages/urllib3/connection.py", line 174, in _new_conn
[2025-02-27T05:56:17.630+0000] {subprocess.py:93} INFO -     conn = connection.create_connection(
[2025-02-27T05:56:17.631+0000] {subprocess.py:93} INFO -   File "/home/***/.local/lib/python3.8/site-packages/urllib3/util/connection.py", line 95, in create_connection
[2025-02-27T05:56:17.631+0000] {subprocess.py:93} INFO -     raise err
[2025-02-27T05:56:17.632+0000] {subprocess.py:93} INFO -   File "/home/***/.local/lib/python3.8/site-packages/urllib3/util/connection.py", line 85, in create_connection
[2025-02-27T05:56:17.632+0000] {subprocess.py:93} INFO -     sock.connect(sa)
[2025-02-27T05:56:17.633+0000] {subprocess.py:93} INFO - ConnectionRefusedError: [Errno 111] Connection refused
[2025-02-27T05:56:17.633+0000] {subprocess.py:93} INFO - 
[2025-02-27T05:56:17.634+0000] {subprocess.py:93} INFO - During handling of the above exception, another exception occurred:
[2025-02-27T05:56:17.634+0000] {subprocess.py:93} INFO - 
[2025-02-27T05:56:17.635+0000] {subprocess.py:93} INFO - Traceback (most recent call last):
[2025-02-27T05:56:17.635+0000] {subprocess.py:93} INFO -   File "/home/***/.local/lib/python3.8/site-packages/urllib3/connectionpool.py", line 715, in urlopen
[2025-02-27T05:56:17.636+0000] {subprocess.py:93} INFO -     httplib_response = self._make_request(
[2025-02-27T05:56:17.636+0000] {subprocess.py:93} INFO -   File "/home/***/.local/lib/python3.8/site-packages/urllib3/connectionpool.py", line 416, in _make_request
[2025-02-27T05:56:17.637+0000] {subprocess.py:93} INFO -     conn.request(method, url, **httplib_request_kw)
[2025-02-27T05:56:17.637+0000] {subprocess.py:93} INFO -   File "/home/***/.local/lib/python3.8/site-packages/urllib3/connection.py", line 244, in request
[2025-02-27T05:56:17.638+0000] {subprocess.py:93} INFO -     super(HTTPConnection, self).request(method, url, body=body, headers=headers)
[2025-02-27T05:56:17.639+0000] {subprocess.py:93} INFO -   File "/usr/local/lib/python3.8/http/client.py", line 1256, in request
[2025-02-27T05:56:17.639+0000] {subprocess.py:93} INFO -     self._send_request(method, url, body, headers, encode_chunked)
[2025-02-27T05:56:17.639+0000] {subprocess.py:93} INFO -   File "/usr/local/lib/python3.8/http/client.py", line 1302, in _send_request
[2025-02-27T05:56:17.640+0000] {subprocess.py:93} INFO -     self.endheaders(body, encode_chunked=encode_chunked)
[2025-02-27T05:56:17.640+0000] {subprocess.py:93} INFO -   File "/usr/local/lib/python3.8/http/client.py", line 1251, in endheaders
[2025-02-27T05:56:17.641+0000] {subprocess.py:93} INFO -     self._send_output(message_body, encode_chunked=encode_chunked)
[2025-02-27T05:56:17.641+0000] {subprocess.py:93} INFO -   File "/usr/local/lib/python3.8/http/client.py", line 1011, in _send_output
[2025-02-27T05:56:17.642+0000] {subprocess.py:93} INFO -     self.send(msg)
[2025-02-27T05:56:17.642+0000] {subprocess.py:93} INFO -   File "/usr/local/lib/python3.8/http/client.py", line 951, in send
[2025-02-27T05:56:17.642+0000] {subprocess.py:93} INFO -     self.connect()
[2025-02-27T05:56:17.643+0000] {subprocess.py:93} INFO -   File "/home/***/.local/lib/python3.8/site-packages/urllib3/connection.py", line 205, in connect
[2025-02-27T05:56:17.644+0000] {subprocess.py:93} INFO -     conn = self._new_conn()
[2025-02-27T05:56:17.644+0000] {subprocess.py:93} INFO -   File "/home/***/.local/lib/python3.8/site-packages/urllib3/connection.py", line 186, in _new_conn
[2025-02-27T05:56:17.645+0000] {subprocess.py:93} INFO -     raise NewConnectionError(
[2025-02-27T05:56:17.645+0000] {subprocess.py:93} INFO - urllib3.exceptions.NewConnectionError: <urllib3.connection.HTTPConnection object at 0x7f3f64003310>: Failed to establish a new connection: [Errno 111] Connection refused
[2025-02-27T05:56:17.646+0000] {subprocess.py:93} INFO - 
[2025-02-27T05:56:17.646+0000] {subprocess.py:93} INFO - During handling of the above exception, another exception occurred:
[2025-02-27T05:56:17.647+0000] {subprocess.py:93} INFO - 
[2025-02-27T05:56:17.647+0000] {subprocess.py:93} INFO - Traceback (most recent call last):
[2025-02-27T05:56:17.647+0000] {subprocess.py:93} INFO -   File "/opt/***/dags/scripts/extract_coingecko.py", line 59, in <module>
[2025-02-27T05:56:17.648+0000] {subprocess.py:93} INFO -     found = minio_client.bucket_exists(bucket_name)
[2025-02-27T05:56:17.648+0000] {subprocess.py:93} INFO -   File "/home/***/.local/lib/python3.8/site-packages/minio/api.py", line 696, in bucket_exists
[2025-02-27T05:56:17.649+0000] {subprocess.py:93} INFO -     self._execute("HEAD", bucket_name)
[2025-02-27T05:56:17.649+0000] {subprocess.py:93} INFO -   File "/home/***/.local/lib/python3.8/site-packages/minio/api.py", line 437, in _execute
[2025-02-27T05:56:17.650+0000] {subprocess.py:93} INFO -     region = self._get_region(bucket_name)
[2025-02-27T05:56:17.650+0000] {subprocess.py:93} INFO -   File "/home/***/.local/lib/python3.8/site-packages/minio/api.py", line 494, in _get_region
[2025-02-27T05:56:17.650+0000] {subprocess.py:93} INFO -     response = self._url_open(
[2025-02-27T05:56:17.651+0000] {subprocess.py:93} INFO -   File "/home/***/.local/lib/python3.8/site-packages/minio/api.py", line 302, in _url_open
[2025-02-27T05:56:17.651+0000] {subprocess.py:93} INFO -     response = self._http.urlopen(
[2025-02-27T05:56:17.651+0000] {subprocess.py:93} INFO -   File "/home/***/.local/lib/python3.8/site-packages/urllib3/poolmanager.py", line 376, in urlopen
[2025-02-27T05:56:17.652+0000] {subprocess.py:93} INFO -     response = conn.urlopen(method, u.request_uri, **kw)
[2025-02-27T05:56:17.653+0000] {subprocess.py:93} INFO -   File "/home/***/.local/lib/python3.8/site-packages/urllib3/connectionpool.py", line 827, in urlopen
[2025-02-27T05:56:17.653+0000] {subprocess.py:93} INFO -     return self.urlopen(
[2025-02-27T05:56:17.653+0000] {subprocess.py:93} INFO -   File "/home/***/.local/lib/python3.8/site-packages/urllib3/connectionpool.py", line 827, in urlopen
[2025-02-27T05:56:17.654+0000] {subprocess.py:93} INFO -     return self.urlopen(
[2025-02-27T05:56:17.654+0000] {subprocess.py:93} INFO -   File "/home/***/.local/lib/python3.8/site-packages/urllib3/connectionpool.py", line 827, in urlopen
[2025-02-27T05:56:17.655+0000] {subprocess.py:93} INFO -     return self.urlopen(
[2025-02-27T05:56:17.655+0000] {subprocess.py:93} INFO -   [Previous line repeated 2 more times]
[2025-02-27T05:56:17.656+0000] {subprocess.py:93} INFO -   File "/home/***/.local/lib/python3.8/site-packages/urllib3/connectionpool.py", line 799, in urlopen
[2025-02-27T05:56:17.656+0000] {subprocess.py:93} INFO -     retries = retries.increment(
[2025-02-27T05:56:17.656+0000] {subprocess.py:93} INFO -   File "/home/***/.local/lib/python3.8/site-packages/urllib3/util/retry.py", line 592, in increment
[2025-02-27T05:56:17.657+0000] {subprocess.py:93} INFO -     raise MaxRetryError(_pool, url, error or ResponseError(cause))
[2025-02-27T05:56:17.657+0000] {subprocess.py:93} INFO - urllib3.exceptions.MaxRetryError: HTTPConnectionPool(host='localhost', port=9000): Max retries exceeded with url: /coin-bucket?location= (Caused by NewConnectionError('<urllib3.connection.HTTPConnection object at 0x7f3f64003310>: Failed to establish a new connection: [Errno 111] Connection refused'))
[2025-02-27T05:56:17.740+0000] {subprocess.py:97} INFO - Command exited with return code 1
[2025-02-27T05:56:17.751+0000] {taskinstance.py:2698} ERROR - Task failed with exception
Traceback (most recent call last):
  File "/home/airflow/.local/lib/python3.8/site-packages/airflow/models/taskinstance.py", line 433, in _execute_task
    result = execute_callable(context=context, **execute_callable_kwargs)
  File "/home/airflow/.local/lib/python3.8/site-packages/airflow/operators/bash.py", line 212, in execute
    raise AirflowException(
airflow.exceptions.AirflowException: Bash command failed. The command returned a non-zero exit code 1.
[2025-02-27T05:56:17.754+0000] {taskinstance.py:1138} INFO - Marking task as FAILED. dag_id=crypto_etl_dag, task_id=extract_coingecko_file, execution_date=20250227T055608, start_date=20250227T055609, end_date=20250227T055617
[2025-02-27T05:56:17.772+0000] {standard_task_runner.py:107} ERROR - Failed to execute job 24 for task extract_coingecko_file (Bash command failed. The command returned a non-zero exit code 1.; 326)
[2025-02-27T05:56:17.787+0000] {local_task_job_runner.py:234} INFO - Task exited with return code 1
[2025-02-27T05:56:17.809+0000] {taskinstance.py:3280} INFO - 0 downstream tasks scheduled from follow-on schedule check
